2019-05-13 23:02:00,137 - root - ERROR -f app.py -m Traceback (most recent call last):
  File "/Users/gring2/workspace/bookMarkLibrary/venv/lib/python3.7/site-packages/pymysql/connections.py", line 583, in connect
    **kwargs)
  File "/usr/local/Cellar/python/3.7.3/Frameworks/Python.framework/Versions/3.7/lib/python3.7/socket.py", line 727, in create_connection
    raise err
  File "/usr/local/Cellar/python/3.7.3/Frameworks/Python.framework/Versions/3.7/lib/python3.7/socket.py", line 716, in create_connection
    sock.connect(sa)
ConnectionRefusedError: [Errno 61] Connection refused

During handling of the above exception, another exception occurred:

Traceback (most recent call last):
  File "/Users/gring2/workspace/bookMarkLibrary/venv/lib/python3.7/site-packages/sqlalchemy/engine/base.py", line 2262, in _wrap_pool_connect
    return fn()
  File "/Users/gring2/workspace/bookMarkLibrary/venv/lib/python3.7/site-packages/sqlalchemy/pool/base.py", line 363, in connect
    return _ConnectionFairy._checkout(self)
  File "/Users/gring2/workspace/bookMarkLibrary/venv/lib/python3.7/site-packages/sqlalchemy/pool/base.py", line 760, in _checkout
    fairy = _ConnectionRecord.checkout(pool)
  File "/Users/gring2/workspace/bookMarkLibrary/venv/lib/python3.7/site-packages/sqlalchemy/pool/base.py", line 492, in checkout
    rec = pool._do_get()
  File "/Users/gring2/workspace/bookMarkLibrary/venv/lib/python3.7/site-packages/sqlalchemy/pool/impl.py", line 139, in _do_get
    self._dec_overflow()
  File "/Users/gring2/workspace/bookMarkLibrary/venv/lib/python3.7/site-packages/sqlalchemy/util/langhelpers.py", line 68, in __exit__
    compat.reraise(exc_type, exc_value, exc_tb)
  File "/Users/gring2/workspace/bookMarkLibrary/venv/lib/python3.7/site-packages/sqlalchemy/util/compat.py", line 129, in reraise
    raise value
  File "/Users/gring2/workspace/bookMarkLibrary/venv/lib/python3.7/site-packages/sqlalchemy/pool/impl.py", line 136, in _do_get
    return self._create_connection()
  File "/Users/gring2/workspace/bookMarkLibrary/venv/lib/python3.7/site-packages/sqlalchemy/pool/base.py", line 308, in _create_connection
    return _ConnectionRecord(self)
  File "/Users/gring2/workspace/bookMarkLibrary/venv/lib/python3.7/site-packages/sqlalchemy/pool/base.py", line 437, in __init__
    self.__connect(first_connect_check=True)
  File "/Users/gring2/workspace/bookMarkLibrary/venv/lib/python3.7/site-packages/sqlalchemy/pool/base.py", line 639, in __connect
    connection = pool._invoke_creator(self)
  File "/Users/gring2/workspace/bookMarkLibrary/venv/lib/python3.7/site-packages/sqlalchemy/engine/strategies.py", line 114, in connect
    return dialect.connect(*cargs, **cparams)
  File "/Users/gring2/workspace/bookMarkLibrary/venv/lib/python3.7/site-packages/sqlalchemy/engine/default.py", line 453, in connect
    return self.dbapi.connect(*cargs, **cparams)
  File "/Users/gring2/workspace/bookMarkLibrary/venv/lib/python3.7/site-packages/pymysql/__init__.py", line 94, in Connect
    return Connection(*args, **kwargs)
  File "/Users/gring2/workspace/bookMarkLibrary/venv/lib/python3.7/site-packages/pymysql/connections.py", line 325, in __init__
    self.connect()
  File "/Users/gring2/workspace/bookMarkLibrary/venv/lib/python3.7/site-packages/pymysql/connections.py", line 630, in connect
    raise exc
pymysql.err.OperationalError: (2003, "Can't connect to MySQL server on 'localhost' ([Errno 61] Connection refused)")

The above exception was the direct cause of the following exception:

Traceback (most recent call last):
  File "/Users/gring2/workspace/bookMarkLibrary/venv/lib/python3.7/site-packages/flask/app.py", line 1811, in full_dispatch_request
    rv = self.preprocess_request()
  File "/Users/gring2/workspace/bookMarkLibrary/venv/lib/python3.7/site-packages/flask/app.py", line 2087, in preprocess_request
    rv = func()
  File "/Users/gring2/workspace/bookMarkLibrary/venv/lib/python3.7/site-packages/flask_principal.py", line 477, in _on_before_request
    identity = loader()
  File "/Users/gring2/workspace/bookMarkLibrary/venv/lib/python3.7/site-packages/flask_security/core.py", line 245, in _identity_loader
    if not isinstance(current_user._get_current_object(), AnonymousUserMixin):
  File "/Users/gring2/workspace/bookMarkLibrary/venv/lib/python3.7/site-packages/werkzeug/local.py", line 306, in _get_current_object
    return self.__local()
  File "/Users/gring2/workspace/bookMarkLibrary/venv/lib/python3.7/site-packages/flask_login/utils.py", line 26, in <lambda>
    current_user = LocalProxy(lambda: _get_user())
  File "/Users/gring2/workspace/bookMarkLibrary/venv/lib/python3.7/site-packages/flask_login/utils.py", line 335, in _get_user
    current_app.login_manager._load_user()
  File "/Users/gring2/workspace/bookMarkLibrary/venv/lib/python3.7/site-packages/flask_login/login_manager.py", line 359, in _load_user
    return self.reload_user()
  File "/Users/gring2/workspace/bookMarkLibrary/venv/lib/python3.7/site-packages/flask_login/login_manager.py", line 321, in reload_user
    user = self.user_callback(user_id)
  File "/Users/gring2/workspace/bookMarkLibrary/venv/lib/python3.7/site-packages/flask_security/core.py", line 221, in _user_loader
    return _security.datastore.find_user(id=user_id)
  File "/Users/gring2/workspace/bookMarkLibrary/venv/lib/python3.7/site-packages/flask_security/datastore.py", line 254, in find_user
    return self.user_model.query.filter_by(**kwargs).first()
  File "/Users/gring2/workspace/bookMarkLibrary/venv/lib/python3.7/site-packages/sqlalchemy/orm/query.py", line 3215, in first
    ret = list(self[0:1])
  File "/Users/gring2/workspace/bookMarkLibrary/venv/lib/python3.7/site-packages/sqlalchemy/orm/query.py", line 3007, in __getitem__
    return list(res)
  File "/Users/gring2/workspace/bookMarkLibrary/venv/lib/python3.7/site-packages/sqlalchemy/orm/query.py", line 3317, in __iter__
    return self._execute_and_instances(context)
  File "/Users/gring2/workspace/bookMarkLibrary/venv/lib/python3.7/site-packages/sqlalchemy/orm/query.py", line 3339, in _execute_and_instances
    querycontext, self._connection_from_session, close_with_result=True
  File "/Users/gring2/workspace/bookMarkLibrary/venv/lib/python3.7/site-packages/sqlalchemy/orm/query.py", line 3354, in _get_bind_args
    mapper=self._bind_mapper(), clause=querycontext.statement, **kw
  File "/Users/gring2/workspace/bookMarkLibrary/venv/lib/python3.7/site-packages/sqlalchemy/orm/query.py", line 3332, in _connection_from_session
    conn = self.session.connection(**kw)
  File "/Users/gring2/workspace/bookMarkLibrary/venv/lib/python3.7/site-packages/sqlalchemy/orm/session.py", line 1123, in connection
    execution_options=execution_options,
  File "/Users/gring2/workspace/bookMarkLibrary/venv/lib/python3.7/site-packages/sqlalchemy/orm/session.py", line 1129, in _connection_for_bind
    engine, execution_options
  File "/Users/gring2/workspace/bookMarkLibrary/venv/lib/python3.7/site-packages/sqlalchemy/orm/session.py", line 430, in _connection_for_bind
    conn = bind._contextual_connect()
  File "/Users/gring2/workspace/bookMarkLibrary/venv/lib/python3.7/site-packages/sqlalchemy/engine/base.py", line 2226, in _contextual_connect
    self._wrap_pool_connect(self.pool.connect, None),
  File "/Users/gring2/workspace/bookMarkLibrary/venv/lib/python3.7/site-packages/sqlalchemy/engine/base.py", line 2266, in _wrap_pool_connect
    e, dialect, self
  File "/Users/gring2/workspace/bookMarkLibrary/venv/lib/python3.7/site-packages/sqlalchemy/engine/base.py", line 1536, in _handle_dbapi_exception_noconnection
    util.raise_from_cause(sqlalchemy_exception, exc_info)
  File "/Users/gring2/workspace/bookMarkLibrary/venv/lib/python3.7/site-packages/sqlalchemy/util/compat.py", line 383, in raise_from_cause
    reraise(type(exception), exception, tb=exc_tb, cause=cause)
  File "/Users/gring2/workspace/bookMarkLibrary/venv/lib/python3.7/site-packages/sqlalchemy/util/compat.py", line 128, in reraise
    raise value.with_traceback(tb)
  File "/Users/gring2/workspace/bookMarkLibrary/venv/lib/python3.7/site-packages/sqlalchemy/engine/base.py", line 2262, in _wrap_pool_connect
    return fn()
  File "/Users/gring2/workspace/bookMarkLibrary/venv/lib/python3.7/site-packages/sqlalchemy/pool/base.py", line 363, in connect
    return _ConnectionFairy._checkout(self)
  File "/Users/gring2/workspace/bookMarkLibrary/venv/lib/python3.7/site-packages/sqlalchemy/pool/base.py", line 760, in _checkout
    fairy = _ConnectionRecord.checkout(pool)
  File "/Users/gring2/workspace/bookMarkLibrary/venv/lib/python3.7/site-packages/sqlalchemy/pool/base.py", line 492, in checkout
    rec = pool._do_get()
  File "/Users/gring2/workspace/bookMarkLibrary/venv/lib/python3.7/site-packages/sqlalchemy/pool/impl.py", line 139, in _do_get
    self._dec_overflow()
  File "/Users/gring2/workspace/bookMarkLibrary/venv/lib/python3.7/site-packages/sqlalchemy/util/langhelpers.py", line 68, in __exit__
    compat.reraise(exc_type, exc_value, exc_tb)
  File "/Users/gring2/workspace/bookMarkLibrary/venv/lib/python3.7/site-packages/sqlalchemy/util/compat.py", line 129, in reraise
    raise value
  File "/Users/gring2/workspace/bookMarkLibrary/venv/lib/python3.7/site-packages/sqlalchemy/pool/impl.py", line 136, in _do_get
    return self._create_connection()
  File "/Users/gring2/workspace/bookMarkLibrary/venv/lib/python3.7/site-packages/sqlalchemy/pool/base.py", line 308, in _create_connection
    return _ConnectionRecord(self)
  File "/Users/gring2/workspace/bookMarkLibrary/venv/lib/python3.7/site-packages/sqlalchemy/pool/base.py", line 437, in __init__
    self.__connect(first_connect_check=True)
  File "/Users/gring2/workspace/bookMarkLibrary/venv/lib/python3.7/site-packages/sqlalchemy/pool/base.py", line 639, in __connect
    connection = pool._invoke_creator(self)
  File "/Users/gring2/workspace/bookMarkLibrary/venv/lib/python3.7/site-packages/sqlalchemy/engine/strategies.py", line 114, in connect
    return dialect.connect(*cargs, **cparams)
  File "/Users/gring2/workspace/bookMarkLibrary/venv/lib/python3.7/site-packages/sqlalchemy/engine/default.py", line 453, in connect
    return self.dbapi.connect(*cargs, **cparams)
  File "/Users/gring2/workspace/bookMarkLibrary/venv/lib/python3.7/site-packages/pymysql/__init__.py", line 94, in Connect
    return Connection(*args, **kwargs)
  File "/Users/gring2/workspace/bookMarkLibrary/venv/lib/python3.7/site-packages/pymysql/connections.py", line 325, in __init__
    self.connect()
  File "/Users/gring2/workspace/bookMarkLibrary/venv/lib/python3.7/site-packages/pymysql/connections.py", line 630, in connect
    raise exc
sqlalchemy.exc.OperationalError: (pymysql.err.OperationalError) (2003, "Can't connect to MySQL server on 'localhost' ([Errno 61] Connection refused)")
(Background on this error at: http://sqlalche.me/e/e3q8)

2019-05-13 23:02:49,552 - root - ERROR -f app.py -m Traceback (most recent call last):
  File "/Users/gring2/workspace/bookMarkLibrary/venv/lib/python3.7/site-packages/flask/app.py", line 1813, in full_dispatch_request
    rv = self.dispatch_request()
  File "/Users/gring2/workspace/bookMarkLibrary/venv/lib/python3.7/site-packages/flask/app.py", line 1791, in dispatch_request
    self.raise_routing_exception(req)
  File "/Users/gring2/workspace/bookMarkLibrary/venv/lib/python3.7/site-packages/flask/app.py", line 1774, in raise_routing_exception
    raise request.routing_exception
  File "/Users/gring2/workspace/bookMarkLibrary/venv/lib/python3.7/site-packages/flask/ctx.py", line 336, in match_request
    self.url_adapter.match(return_rule=True)
  File "/Users/gring2/workspace/bookMarkLibrary/venv/lib/python3.7/site-packages/werkzeug/routing.py", line 1581, in match
    raise NotFound()
werkzeug.exceptions.NotFound: 404 Not Found: The requested URL was not found on the server.  If you entered the URL manually please check your spelling and try again.

2019-05-13 23:02:51,252 - root - ERROR -f app.py -m Traceback (most recent call last):
  File "/Users/gring2/workspace/bookMarkLibrary/venv/lib/python3.7/site-packages/sqlalchemy/engine/base.py", line 1244, in _execute_context
    cursor, statement, parameters, context
  File "/Users/gring2/workspace/bookMarkLibrary/venv/lib/python3.7/site-packages/sqlalchemy/engine/default.py", line 552, in do_execute
    cursor.execute(statement, parameters)
  File "/Users/gring2/workspace/bookMarkLibrary/venv/lib/python3.7/site-packages/pymysql/cursors.py", line 170, in execute
    result = self._query(query)
  File "/Users/gring2/workspace/bookMarkLibrary/venv/lib/python3.7/site-packages/pymysql/cursors.py", line 328, in _query
    conn.query(q)
  File "/Users/gring2/workspace/bookMarkLibrary/venv/lib/python3.7/site-packages/pymysql/connections.py", line 517, in query
    self._affected_rows = self._read_query_result(unbuffered=unbuffered)
  File "/Users/gring2/workspace/bookMarkLibrary/venv/lib/python3.7/site-packages/pymysql/connections.py", line 732, in _read_query_result
    result.read()
  File "/Users/gring2/workspace/bookMarkLibrary/venv/lib/python3.7/site-packages/pymysql/connections.py", line 1075, in read
    first_packet = self.connection._read_packet()
  File "/Users/gring2/workspace/bookMarkLibrary/venv/lib/python3.7/site-packages/pymysql/connections.py", line 684, in _read_packet
    packet.check_error()
  File "/Users/gring2/workspace/bookMarkLibrary/venv/lib/python3.7/site-packages/pymysql/protocol.py", line 220, in check_error
    err.raise_mysql_exception(self._data)
  File "/Users/gring2/workspace/bookMarkLibrary/venv/lib/python3.7/site-packages/pymysql/err.py", line 109, in raise_mysql_exception
    raise errorclass(errno, errval)
pymysql.err.InternalError: (1054, "Unknown column 'bookmarks.user_id' in 'field list'")

The above exception was the direct cause of the following exception:

Traceback (most recent call last):
  File "/Users/gring2/workspace/bookMarkLibrary/venv/lib/python3.7/site-packages/flask/app.py", line 1813, in full_dispatch_request
    rv = self.dispatch_request()
  File "/Users/gring2/workspace/bookMarkLibrary/venv/lib/python3.7/site-packages/flask/app.py", line 1799, in dispatch_request
    return self.view_functions[rule.endpoint](**req.view_args)
  File "/Users/gring2/workspace/bookMarkLibrary/venv/lib/python3.7/site-packages/flask_login/utils.py", line 261, in decorated_view
    return func(*args, **kwargs)
  File "/Users/gring2/workspace/bookMarkLibrary/library/view.py", line 30, in urls
    bookMarks = current_user.bookmarks
  File "/Users/gring2/workspace/bookMarkLibrary/venv/lib/python3.7/site-packages/werkzeug/local.py", line 347, in __getattr__
    return getattr(self._get_current_object(), name)
  File "/Users/gring2/workspace/bookMarkLibrary/venv/lib/python3.7/site-packages/sqlalchemy/orm/attributes.py", line 276, in __get__
    return self.impl.get(instance_state(instance), dict_)
  File "/Users/gring2/workspace/bookMarkLibrary/venv/lib/python3.7/site-packages/sqlalchemy/orm/attributes.py", line 682, in get
    value = self.callable_(state, passive)
  File "/Users/gring2/workspace/bookMarkLibrary/venv/lib/python3.7/site-packages/sqlalchemy/orm/strategies.py", line 723, in _load_for_state
    session, state, primary_key_identity, passive
  File "<string>", line 1, in <lambda>
  File "/Users/gring2/workspace/bookMarkLibrary/venv/lib/python3.7/site-packages/sqlalchemy/orm/strategies.py", line 865, in _emit_lazyload
    .with_post_criteria(set_default_params)
  File "/Users/gring2/workspace/bookMarkLibrary/venv/lib/python3.7/site-packages/sqlalchemy/ext/baked.py", line 531, in all
    return list(self)
  File "/Users/gring2/workspace/bookMarkLibrary/venv/lib/python3.7/site-packages/sqlalchemy/ext/baked.py", line 434, in __iter__
    return q._execute_and_instances(context)
  File "/Users/gring2/workspace/bookMarkLibrary/venv/lib/python3.7/site-packages/sqlalchemy/orm/query.py", line 3342, in _execute_and_instances
    result = conn.execute(querycontext.statement, self._params)
  File "/Users/gring2/workspace/bookMarkLibrary/venv/lib/python3.7/site-packages/sqlalchemy/engine/base.py", line 988, in execute
    return meth(self, multiparams, params)
  File "/Users/gring2/workspace/bookMarkLibrary/venv/lib/python3.7/site-packages/sqlalchemy/sql/elements.py", line 287, in _execute_on_connection
    return connection._execute_clauseelement(self, multiparams, params)
  File "/Users/gring2/workspace/bookMarkLibrary/venv/lib/python3.7/site-packages/sqlalchemy/engine/base.py", line 1107, in _execute_clauseelement
    distilled_params,
  File "/Users/gring2/workspace/bookMarkLibrary/venv/lib/python3.7/site-packages/sqlalchemy/engine/base.py", line 1248, in _execute_context
    e, statement, parameters, cursor, context
  File "/Users/gring2/workspace/bookMarkLibrary/venv/lib/python3.7/site-packages/sqlalchemy/engine/base.py", line 1466, in _handle_dbapi_exception
    util.raise_from_cause(sqlalchemy_exception, exc_info)
  File "/Users/gring2/workspace/bookMarkLibrary/venv/lib/python3.7/site-packages/sqlalchemy/util/compat.py", line 383, in raise_from_cause
    reraise(type(exception), exception, tb=exc_tb, cause=cause)
  File "/Users/gring2/workspace/bookMarkLibrary/venv/lib/python3.7/site-packages/sqlalchemy/util/compat.py", line 128, in reraise
    raise value.with_traceback(tb)
  File "/Users/gring2/workspace/bookMarkLibrary/venv/lib/python3.7/site-packages/sqlalchemy/engine/base.py", line 1244, in _execute_context
    cursor, statement, parameters, context
  File "/Users/gring2/workspace/bookMarkLibrary/venv/lib/python3.7/site-packages/sqlalchemy/engine/default.py", line 552, in do_execute
    cursor.execute(statement, parameters)
  File "/Users/gring2/workspace/bookMarkLibrary/venv/lib/python3.7/site-packages/pymysql/cursors.py", line 170, in execute
    result = self._query(query)
  File "/Users/gring2/workspace/bookMarkLibrary/venv/lib/python3.7/site-packages/pymysql/cursors.py", line 328, in _query
    conn.query(q)
  File "/Users/gring2/workspace/bookMarkLibrary/venv/lib/python3.7/site-packages/pymysql/connections.py", line 517, in query
    self._affected_rows = self._read_query_result(unbuffered=unbuffered)
  File "/Users/gring2/workspace/bookMarkLibrary/venv/lib/python3.7/site-packages/pymysql/connections.py", line 732, in _read_query_result
    result.read()
  File "/Users/gring2/workspace/bookMarkLibrary/venv/lib/python3.7/site-packages/pymysql/connections.py", line 1075, in read
    first_packet = self.connection._read_packet()
  File "/Users/gring2/workspace/bookMarkLibrary/venv/lib/python3.7/site-packages/pymysql/connections.py", line 684, in _read_packet
    packet.check_error()
  File "/Users/gring2/workspace/bookMarkLibrary/venv/lib/python3.7/site-packages/pymysql/protocol.py", line 220, in check_error
    err.raise_mysql_exception(self._data)
  File "/Users/gring2/workspace/bookMarkLibrary/venv/lib/python3.7/site-packages/pymysql/err.py", line 109, in raise_mysql_exception
    raise errorclass(errno, errval)
sqlalchemy.exc.InternalError: (pymysql.err.InternalError) (1054, "Unknown column 'bookmarks.user_id' in 'field list'")
[SQL: SELECT bookmarks.id AS bookmarks_id, bookmarks._url AS bookmarks__url, bookmarks.user_id AS bookmarks_user_id, bookmarks.img AS bookmarks_img, bookmarks.name AS bookmarks_name, bookmarks.created_at AS bookmarks_created_at, bookmarks.updated_at AS bookmarks_updated_at 
FROM bookmarks 
WHERE %(param_1)s = bookmarks.user_id]
[parameters: {'param_1': 1}]
(Background on this error at: http://sqlalche.me/e/2j85)

2019-05-13 23:03:01,075 - root - ERROR -f app.py -m Traceback (most recent call last):
  File "/Users/gring2/workspace/bookMarkLibrary/venv/lib/python3.7/site-packages/sqlalchemy/engine/base.py", line 1244, in _execute_context
    cursor, statement, parameters, context
  File "/Users/gring2/workspace/bookMarkLibrary/venv/lib/python3.7/site-packages/sqlalchemy/engine/default.py", line 552, in do_execute
    cursor.execute(statement, parameters)
  File "/Users/gring2/workspace/bookMarkLibrary/venv/lib/python3.7/site-packages/pymysql/cursors.py", line 170, in execute
    result = self._query(query)
  File "/Users/gring2/workspace/bookMarkLibrary/venv/lib/python3.7/site-packages/pymysql/cursors.py", line 328, in _query
    conn.query(q)
  File "/Users/gring2/workspace/bookMarkLibrary/venv/lib/python3.7/site-packages/pymysql/connections.py", line 517, in query
    self._affected_rows = self._read_query_result(unbuffered=unbuffered)
  File "/Users/gring2/workspace/bookMarkLibrary/venv/lib/python3.7/site-packages/pymysql/connections.py", line 732, in _read_query_result
    result.read()
  File "/Users/gring2/workspace/bookMarkLibrary/venv/lib/python3.7/site-packages/pymysql/connections.py", line 1075, in read
    first_packet = self.connection._read_packet()
  File "/Users/gring2/workspace/bookMarkLibrary/venv/lib/python3.7/site-packages/pymysql/connections.py", line 684, in _read_packet
    packet.check_error()
  File "/Users/gring2/workspace/bookMarkLibrary/venv/lib/python3.7/site-packages/pymysql/protocol.py", line 220, in check_error
    err.raise_mysql_exception(self._data)
  File "/Users/gring2/workspace/bookMarkLibrary/venv/lib/python3.7/site-packages/pymysql/err.py", line 109, in raise_mysql_exception
    raise errorclass(errno, errval)
pymysql.err.InternalError: (1054, "Unknown column 'bookmarks.user_id' in 'field list'")

The above exception was the direct cause of the following exception:

Traceback (most recent call last):
  File "/Users/gring2/workspace/bookMarkLibrary/venv/lib/python3.7/site-packages/flask/app.py", line 1813, in full_dispatch_request
    rv = self.dispatch_request()
  File "/Users/gring2/workspace/bookMarkLibrary/venv/lib/python3.7/site-packages/flask/app.py", line 1799, in dispatch_request
    return self.view_functions[rule.endpoint](**req.view_args)
  File "/Users/gring2/workspace/bookMarkLibrary/venv/lib/python3.7/site-packages/flask_login/utils.py", line 261, in decorated_view
    return func(*args, **kwargs)
  File "/Users/gring2/workspace/bookMarkLibrary/library/view.py", line 30, in urls
    bookMarks = current_user.bookmarks
  File "/Users/gring2/workspace/bookMarkLibrary/venv/lib/python3.7/site-packages/werkzeug/local.py", line 347, in __getattr__
    return getattr(self._get_current_object(), name)
  File "/Users/gring2/workspace/bookMarkLibrary/venv/lib/python3.7/site-packages/sqlalchemy/orm/attributes.py", line 276, in __get__
    return self.impl.get(instance_state(instance), dict_)
  File "/Users/gring2/workspace/bookMarkLibrary/venv/lib/python3.7/site-packages/sqlalchemy/orm/attributes.py", line 682, in get
    value = self.callable_(state, passive)
  File "/Users/gring2/workspace/bookMarkLibrary/venv/lib/python3.7/site-packages/sqlalchemy/orm/strategies.py", line 723, in _load_for_state
    session, state, primary_key_identity, passive
  File "<string>", line 1, in <lambda>
  File "/Users/gring2/workspace/bookMarkLibrary/venv/lib/python3.7/site-packages/sqlalchemy/orm/strategies.py", line 865, in _emit_lazyload
    .with_post_criteria(set_default_params)
  File "/Users/gring2/workspace/bookMarkLibrary/venv/lib/python3.7/site-packages/sqlalchemy/ext/baked.py", line 531, in all
    return list(self)
  File "/Users/gring2/workspace/bookMarkLibrary/venv/lib/python3.7/site-packages/sqlalchemy/ext/baked.py", line 434, in __iter__
    return q._execute_and_instances(context)
  File "/Users/gring2/workspace/bookMarkLibrary/venv/lib/python3.7/site-packages/sqlalchemy/orm/query.py", line 3342, in _execute_and_instances
    result = conn.execute(querycontext.statement, self._params)
  File "/Users/gring2/workspace/bookMarkLibrary/venv/lib/python3.7/site-packages/sqlalchemy/engine/base.py", line 988, in execute
    return meth(self, multiparams, params)
  File "/Users/gring2/workspace/bookMarkLibrary/venv/lib/python3.7/site-packages/sqlalchemy/sql/elements.py", line 287, in _execute_on_connection
    return connection._execute_clauseelement(self, multiparams, params)
  File "/Users/gring2/workspace/bookMarkLibrary/venv/lib/python3.7/site-packages/sqlalchemy/engine/base.py", line 1107, in _execute_clauseelement
    distilled_params,
  File "/Users/gring2/workspace/bookMarkLibrary/venv/lib/python3.7/site-packages/sqlalchemy/engine/base.py", line 1248, in _execute_context
    e, statement, parameters, cursor, context
  File "/Users/gring2/workspace/bookMarkLibrary/venv/lib/python3.7/site-packages/sqlalchemy/engine/base.py", line 1466, in _handle_dbapi_exception
    util.raise_from_cause(sqlalchemy_exception, exc_info)
  File "/Users/gring2/workspace/bookMarkLibrary/venv/lib/python3.7/site-packages/sqlalchemy/util/compat.py", line 383, in raise_from_cause
    reraise(type(exception), exception, tb=exc_tb, cause=cause)
  File "/Users/gring2/workspace/bookMarkLibrary/venv/lib/python3.7/site-packages/sqlalchemy/util/compat.py", line 128, in reraise
    raise value.with_traceback(tb)
  File "/Users/gring2/workspace/bookMarkLibrary/venv/lib/python3.7/site-packages/sqlalchemy/engine/base.py", line 1244, in _execute_context
    cursor, statement, parameters, context
  File "/Users/gring2/workspace/bookMarkLibrary/venv/lib/python3.7/site-packages/sqlalchemy/engine/default.py", line 552, in do_execute
    cursor.execute(statement, parameters)
  File "/Users/gring2/workspace/bookMarkLibrary/venv/lib/python3.7/site-packages/pymysql/cursors.py", line 170, in execute
    result = self._query(query)
  File "/Users/gring2/workspace/bookMarkLibrary/venv/lib/python3.7/site-packages/pymysql/cursors.py", line 328, in _query
    conn.query(q)
  File "/Users/gring2/workspace/bookMarkLibrary/venv/lib/python3.7/site-packages/pymysql/connections.py", line 517, in query
    self._affected_rows = self._read_query_result(unbuffered=unbuffered)
  File "/Users/gring2/workspace/bookMarkLibrary/venv/lib/python3.7/site-packages/pymysql/connections.py", line 732, in _read_query_result
    result.read()
  File "/Users/gring2/workspace/bookMarkLibrary/venv/lib/python3.7/site-packages/pymysql/connections.py", line 1075, in read
    first_packet = self.connection._read_packet()
  File "/Users/gring2/workspace/bookMarkLibrary/venv/lib/python3.7/site-packages/pymysql/connections.py", line 684, in _read_packet
    packet.check_error()
  File "/Users/gring2/workspace/bookMarkLibrary/venv/lib/python3.7/site-packages/pymysql/protocol.py", line 220, in check_error
    err.raise_mysql_exception(self._data)
  File "/Users/gring2/workspace/bookMarkLibrary/venv/lib/python3.7/site-packages/pymysql/err.py", line 109, in raise_mysql_exception
    raise errorclass(errno, errval)
sqlalchemy.exc.InternalError: (pymysql.err.InternalError) (1054, "Unknown column 'bookmarks.user_id' in 'field list'")
[SQL: SELECT bookmarks.id AS bookmarks_id, bookmarks._url AS bookmarks__url, bookmarks.user_id AS bookmarks_user_id, bookmarks.img AS bookmarks_img, bookmarks.name AS bookmarks_name, bookmarks.created_at AS bookmarks_created_at, bookmarks.updated_at AS bookmarks_updated_at 
FROM bookmarks 
WHERE %(param_1)s = bookmarks.user_id]
[parameters: {'param_1': 1}]
(Background on this error at: http://sqlalche.me/e/2j85)

2019-05-13 23:11:12,168 - root - ERROR -f app.py -m Traceback (most recent call last):
  File "/Users/gring2/workspace/bookMarkLibrary/venv/lib/python3.7/site-packages/flask/app.py", line 1813, in full_dispatch_request
    rv = self.dispatch_request()
  File "/Users/gring2/workspace/bookMarkLibrary/venv/lib/python3.7/site-packages/flask/app.py", line 1791, in dispatch_request
    self.raise_routing_exception(req)
  File "/Users/gring2/workspace/bookMarkLibrary/venv/lib/python3.7/site-packages/flask/app.py", line 1774, in raise_routing_exception
    raise request.routing_exception
  File "/Users/gring2/workspace/bookMarkLibrary/venv/lib/python3.7/site-packages/flask/ctx.py", line 336, in match_request
    self.url_adapter.match(return_rule=True)
  File "/Users/gring2/workspace/bookMarkLibrary/venv/lib/python3.7/site-packages/werkzeug/routing.py", line 1581, in match
    raise NotFound()
werkzeug.exceptions.NotFound: 404 Not Found: The requested URL was not found on the server.  If you entered the URL manually please check your spelling and try again.

2019-05-13 23:11:58,850 - root - ERROR -f app.py -m Traceback (most recent call last):
  File "/Users/gring2/workspace/bookMarkLibrary/venv/lib/python3.7/site-packages/flask/app.py", line 1813, in full_dispatch_request
    rv = self.dispatch_request()
  File "/Users/gring2/workspace/bookMarkLibrary/venv/lib/python3.7/site-packages/flask/app.py", line 1791, in dispatch_request
    self.raise_routing_exception(req)
  File "/Users/gring2/workspace/bookMarkLibrary/venv/lib/python3.7/site-packages/flask/app.py", line 1774, in raise_routing_exception
    raise request.routing_exception
  File "/Users/gring2/workspace/bookMarkLibrary/venv/lib/python3.7/site-packages/flask/ctx.py", line 336, in match_request
    self.url_adapter.match(return_rule=True)
  File "/Users/gring2/workspace/bookMarkLibrary/venv/lib/python3.7/site-packages/werkzeug/routing.py", line 1581, in match
    raise NotFound()
werkzeug.exceptions.NotFound: 404 Not Found: The requested URL was not found on the server.  If you entered the URL manually please check your spelling and try again.

2019-05-13 23:12:08,983 - root - ERROR -f contract.py -m Traceback (most recent call last):
  File "/Users/gring2/workspace/bookMarkLibrary/venv/lib/python3.7/site-packages/sqlalchemy/engine/base.py", line 1244, in _execute_context
    cursor, statement, parameters, context
  File "/Users/gring2/workspace/bookMarkLibrary/venv/lib/python3.7/site-packages/sqlalchemy/engine/default.py", line 552, in do_execute
    cursor.execute(statement, parameters)
  File "/Users/gring2/workspace/bookMarkLibrary/venv/lib/python3.7/site-packages/pymysql/cursors.py", line 170, in execute
    result = self._query(query)
  File "/Users/gring2/workspace/bookMarkLibrary/venv/lib/python3.7/site-packages/pymysql/cursors.py", line 328, in _query
    conn.query(q)
  File "/Users/gring2/workspace/bookMarkLibrary/venv/lib/python3.7/site-packages/pymysql/connections.py", line 517, in query
    self._affected_rows = self._read_query_result(unbuffered=unbuffered)
  File "/Users/gring2/workspace/bookMarkLibrary/venv/lib/python3.7/site-packages/pymysql/connections.py", line 732, in _read_query_result
    result.read()
  File "/Users/gring2/workspace/bookMarkLibrary/venv/lib/python3.7/site-packages/pymysql/connections.py", line 1075, in read
    first_packet = self.connection._read_packet()
  File "/Users/gring2/workspace/bookMarkLibrary/venv/lib/python3.7/site-packages/pymysql/connections.py", line 684, in _read_packet
    packet.check_error()
  File "/Users/gring2/workspace/bookMarkLibrary/venv/lib/python3.7/site-packages/pymysql/protocol.py", line 220, in check_error
    err.raise_mysql_exception(self._data)
  File "/Users/gring2/workspace/bookMarkLibrary/venv/lib/python3.7/site-packages/pymysql/err.py", line 109, in raise_mysql_exception
    raise errorclass(errno, errval)
pymysql.err.InternalError: (1366, "Incorrect integer value: 'google' for column 'tag' at row 1")

The above exception was the direct cause of the following exception:

Traceback (most recent call last):
  File "/Users/gring2/workspace/bookMarkLibrary/library/contract.py", line 10, in register_bookmark_and_tag
    db.session.commit()
  File "/Users/gring2/workspace/bookMarkLibrary/venv/lib/python3.7/site-packages/sqlalchemy/orm/scoping.py", line 162, in do
    return getattr(self.registry(), name)(*args, **kwargs)
  File "/Users/gring2/workspace/bookMarkLibrary/venv/lib/python3.7/site-packages/sqlalchemy/orm/session.py", line 1026, in commit
    self.transaction.commit()
  File "/Users/gring2/workspace/bookMarkLibrary/venv/lib/python3.7/site-packages/sqlalchemy/orm/session.py", line 493, in commit
    self._prepare_impl()
  File "/Users/gring2/workspace/bookMarkLibrary/venv/lib/python3.7/site-packages/sqlalchemy/orm/session.py", line 472, in _prepare_impl
    self.session.flush()
  File "/Users/gring2/workspace/bookMarkLibrary/venv/lib/python3.7/site-packages/sqlalchemy/orm/session.py", line 2451, in flush
    self._flush(objects)
  File "/Users/gring2/workspace/bookMarkLibrary/venv/lib/python3.7/site-packages/sqlalchemy/orm/session.py", line 2589, in _flush
    transaction.rollback(_capture_exception=True)
  File "/Users/gring2/workspace/bookMarkLibrary/venv/lib/python3.7/site-packages/sqlalchemy/util/langhelpers.py", line 68, in __exit__
    compat.reraise(exc_type, exc_value, exc_tb)
  File "/Users/gring2/workspace/bookMarkLibrary/venv/lib/python3.7/site-packages/sqlalchemy/util/compat.py", line 129, in reraise
    raise value
  File "/Users/gring2/workspace/bookMarkLibrary/venv/lib/python3.7/site-packages/sqlalchemy/orm/session.py", line 2549, in _flush
    flush_context.execute()
  File "/Users/gring2/workspace/bookMarkLibrary/venv/lib/python3.7/site-packages/sqlalchemy/orm/unitofwork.py", line 422, in execute
    rec.execute(self)
  File "/Users/gring2/workspace/bookMarkLibrary/venv/lib/python3.7/site-packages/sqlalchemy/orm/unitofwork.py", line 589, in execute
    uow,
  File "/Users/gring2/workspace/bookMarkLibrary/venv/lib/python3.7/site-packages/sqlalchemy/orm/persistence.py", line 245, in save_obj
    insert,
  File "/Users/gring2/workspace/bookMarkLibrary/venv/lib/python3.7/site-packages/sqlalchemy/orm/persistence.py", line 1120, in _emit_insert_statements
    statement, params
  File "/Users/gring2/workspace/bookMarkLibrary/venv/lib/python3.7/site-packages/sqlalchemy/engine/base.py", line 988, in execute
    return meth(self, multiparams, params)
  File "/Users/gring2/workspace/bookMarkLibrary/venv/lib/python3.7/site-packages/sqlalchemy/sql/elements.py", line 287, in _execute_on_connection
    return connection._execute_clauseelement(self, multiparams, params)
  File "/Users/gring2/workspace/bookMarkLibrary/venv/lib/python3.7/site-packages/sqlalchemy/engine/base.py", line 1107, in _execute_clauseelement
    distilled_params,
  File "/Users/gring2/workspace/bookMarkLibrary/venv/lib/python3.7/site-packages/sqlalchemy/engine/base.py", line 1248, in _execute_context
    e, statement, parameters, cursor, context
  File "/Users/gring2/workspace/bookMarkLibrary/venv/lib/python3.7/site-packages/sqlalchemy/engine/base.py", line 1466, in _handle_dbapi_exception
    util.raise_from_cause(sqlalchemy_exception, exc_info)
  File "/Users/gring2/workspace/bookMarkLibrary/venv/lib/python3.7/site-packages/sqlalchemy/util/compat.py", line 383, in raise_from_cause
    reraise(type(exception), exception, tb=exc_tb, cause=cause)
  File "/Users/gring2/workspace/bookMarkLibrary/venv/lib/python3.7/site-packages/sqlalchemy/util/compat.py", line 128, in reraise
    raise value.with_traceback(tb)
  File "/Users/gring2/workspace/bookMarkLibrary/venv/lib/python3.7/site-packages/sqlalchemy/engine/base.py", line 1244, in _execute_context
    cursor, statement, parameters, context
  File "/Users/gring2/workspace/bookMarkLibrary/venv/lib/python3.7/site-packages/sqlalchemy/engine/default.py", line 552, in do_execute
    cursor.execute(statement, parameters)
  File "/Users/gring2/workspace/bookMarkLibrary/venv/lib/python3.7/site-packages/pymysql/cursors.py", line 170, in execute
    result = self._query(query)
  File "/Users/gring2/workspace/bookMarkLibrary/venv/lib/python3.7/site-packages/pymysql/cursors.py", line 328, in _query
    conn.query(q)
  File "/Users/gring2/workspace/bookMarkLibrary/venv/lib/python3.7/site-packages/pymysql/connections.py", line 517, in query
    self._affected_rows = self._read_query_result(unbuffered=unbuffered)
  File "/Users/gring2/workspace/bookMarkLibrary/venv/lib/python3.7/site-packages/pymysql/connections.py", line 732, in _read_query_result
    result.read()
  File "/Users/gring2/workspace/bookMarkLibrary/venv/lib/python3.7/site-packages/pymysql/connections.py", line 1075, in read
    first_packet = self.connection._read_packet()
  File "/Users/gring2/workspace/bookMarkLibrary/venv/lib/python3.7/site-packages/pymysql/connections.py", line 684, in _read_packet
    packet.check_error()
  File "/Users/gring2/workspace/bookMarkLibrary/venv/lib/python3.7/site-packages/pymysql/protocol.py", line 220, in check_error
    err.raise_mysql_exception(self._data)
  File "/Users/gring2/workspace/bookMarkLibrary/venv/lib/python3.7/site-packages/pymysql/err.py", line 109, in raise_mysql_exception
    raise errorclass(errno, errval)
sqlalchemy.exc.InternalError: (pymysql.err.InternalError) (1366, "Incorrect integer value: 'google' for column 'tag' at row 1")
[SQL: INSERT INTO tags (id, tag) VALUES (%(id)s, %(tag)s)]
[parameters: {'id': '5d44b431c41341bca4d2bf3284f01364', 'tag': 'google'}]
(Background on this error at: http://sqlalche.me/e/2j85)

2019-05-13 23:21:06,035 - root - ERROR -f app.py -m Traceback (most recent call last):
  File "/Users/gring2/workspace/bookMarkLibrary/venv/lib/python3.7/site-packages/flask/app.py", line 1813, in full_dispatch_request
    rv = self.dispatch_request()
  File "/Users/gring2/workspace/bookMarkLibrary/venv/lib/python3.7/site-packages/flask/app.py", line 1791, in dispatch_request
    self.raise_routing_exception(req)
  File "/Users/gring2/workspace/bookMarkLibrary/venv/lib/python3.7/site-packages/flask/app.py", line 1774, in raise_routing_exception
    raise request.routing_exception
  File "/Users/gring2/workspace/bookMarkLibrary/venv/lib/python3.7/site-packages/flask/ctx.py", line 336, in match_request
    self.url_adapter.match(return_rule=True)
  File "/Users/gring2/workspace/bookMarkLibrary/venv/lib/python3.7/site-packages/werkzeug/routing.py", line 1581, in match
    raise NotFound()
werkzeug.exceptions.NotFound: 404 Not Found: The requested URL was not found on the server.  If you entered the URL manually please check your spelling and try again.

2019-05-14 00:17:24,068 - root - ERROR -f app.py -m Traceback (most recent call last):
  File "/Users/gring2/workspace/bookMarkLibrary/venv/lib/python3.7/site-packages/flask/app.py", line 1813, in full_dispatch_request
    rv = self.dispatch_request()
  File "/Users/gring2/workspace/bookMarkLibrary/venv/lib/python3.7/site-packages/flask/app.py", line 1791, in dispatch_request
    self.raise_routing_exception(req)
  File "/Users/gring2/workspace/bookMarkLibrary/venv/lib/python3.7/site-packages/flask/app.py", line 1774, in raise_routing_exception
    raise request.routing_exception
  File "/Users/gring2/workspace/bookMarkLibrary/venv/lib/python3.7/site-packages/flask/ctx.py", line 336, in match_request
    self.url_adapter.match(return_rule=True)
  File "/Users/gring2/workspace/bookMarkLibrary/venv/lib/python3.7/site-packages/werkzeug/routing.py", line 1581, in match
    raise NotFound()
werkzeug.exceptions.NotFound: 404 Not Found: The requested URL was not found on the server.  If you entered the URL manually please check your spelling and try again.

