2019-05-02 00:52:14,581 - root - ERROR -f test_http.py -m error
2019-05-02 00:52:14,581 - root - WARNING -f test_http.py -m critical
2019-05-02 00:52:14,581 - root - CRITICAL -f test_http.py -m warning
2019-05-02 00:56:02,025 - root - ERROR -f models.py -m Traceback (most recent call last):
  File "/Users/gring2/workspace/bookMarkLibrary/library/models.py", line 90, in save
    file_name = create_thumbnail(self.url)
  File "/Users/gring2/workspace/bookMarkLibrary/handlers/thumbnail_handler.py", line 21, in create_thumbnail
    thumbnail_path = favicon_handler.get_url()
  File "/Users/gring2/workspace/bookMarkLibrary/handlers/image_handler.py", line 76, in get_url
    return self._node['content']
AttributeError: 'FaviconHandler' object has no attribute '_favicon'

2019-05-02 00:56:05,186 - root - ERROR -f models.py -m Traceback (most recent call last):
  File "/Users/gring2/workspace/bookMarkLibrary/venv/lib/python3.7/site-packages/urllib3/connection.py", line 159, in _new_conn
    (self._dns_host, self.port), self.timeout, **extra_kw)
  File "/Users/gring2/workspace/bookMarkLibrary/venv/lib/python3.7/site-packages/urllib3/util/connection.py", line 57, in create_connection
    for res in socket.getaddrinfo(host, port, family, socket.SOCK_STREAM):
  File "/usr/local/Cellar/python/3.7.3/Frameworks/Python.framework/Versions/3.7/lib/python3.7/socket.py", line 748, in getaddrinfo
    for res in _socket.getaddrinfo(host, port, family, type, proto, flags):
socket.gaierror: [Errno 8] nodename nor servname provided, or not known

During handling of the above exception, another exception occurred:

Traceback (most recent call last):
  File "/Users/gring2/workspace/bookMarkLibrary/venv/lib/python3.7/site-packages/urllib3/connectionpool.py", line 600, in urlopen
    chunked=chunked)
  File "/Users/gring2/workspace/bookMarkLibrary/venv/lib/python3.7/site-packages/urllib3/connectionpool.py", line 354, in _make_request
    conn.request(method, url, **httplib_request_kw)
  File "/usr/local/Cellar/python/3.7.3/Frameworks/Python.framework/Versions/3.7/lib/python3.7/http/client.py", line 1229, in request
    self._send_request(method, url, body, headers, encode_chunked)
  File "/usr/local/Cellar/python/3.7.3/Frameworks/Python.framework/Versions/3.7/lib/python3.7/http/client.py", line 1275, in _send_request
    self.endheaders(body, encode_chunked=encode_chunked)
  File "/usr/local/Cellar/python/3.7.3/Frameworks/Python.framework/Versions/3.7/lib/python3.7/http/client.py", line 1224, in endheaders
    self._send_output(message_body, encode_chunked=encode_chunked)
  File "/usr/local/Cellar/python/3.7.3/Frameworks/Python.framework/Versions/3.7/lib/python3.7/http/client.py", line 1016, in _send_output
    self.send(msg)
  File "/usr/local/Cellar/python/3.7.3/Frameworks/Python.framework/Versions/3.7/lib/python3.7/http/client.py", line 956, in send
    self.connect()
  File "/Users/gring2/workspace/bookMarkLibrary/venv/lib/python3.7/site-packages/urllib3/connection.py", line 181, in connect
    conn = self._new_conn()
  File "/Users/gring2/workspace/bookMarkLibrary/venv/lib/python3.7/site-packages/urllib3/connection.py", line 168, in _new_conn
    self, "Failed to establish a new connection: %s" % e)
urllib3.exceptions.NewConnectionError: <urllib3.connection.HTTPConnection object at 0x10f8d0b38>: Failed to establish a new connection: [Errno 8] nodename nor servname provided, or not known

During handling of the above exception, another exception occurred:

Traceback (most recent call last):
  File "/Users/gring2/workspace/bookMarkLibrary/venv/lib/python3.7/site-packages/requests/adapters.py", line 449, in send
    timeout=timeout
  File "/Users/gring2/workspace/bookMarkLibrary/venv/lib/python3.7/site-packages/urllib3/connectionpool.py", line 638, in urlopen
    _stacktrace=sys.exc_info()[2])
  File "/Users/gring2/workspace/bookMarkLibrary/venv/lib/python3.7/site-packages/urllib3/util/retry.py", line 398, in increment
    raise MaxRetryError(_pool, url, error or ResponseError(cause))
urllib3.exceptions.MaxRetryError: HTTPConnectionPool(host='sub%20bookmark', port=80): Max retries exceeded with url: / (Caused by NewConnectionError('<urllib3.connection.HTTPConnection object at 0x10f8d0b38>: Failed to establish a new connection: [Errno 8] nodename nor servname provided, or not known'))

During handling of the above exception, another exception occurred:

Traceback (most recent call last):
  File "/Users/gring2/workspace/bookMarkLibrary/library/models.py", line 90, in save
    file_name = create_thumbnail(self.url)
  File "/Users/gring2/workspace/bookMarkLibrary/handlers/thumbnail_handler.py", line 8, in create_thumbnail
    response = requests.get(url)
  File "/Users/gring2/workspace/bookMarkLibrary/venv/lib/python3.7/site-packages/requests/api.py", line 75, in get
    return request('get', url, params=params, **kwargs)
  File "/Users/gring2/workspace/bookMarkLibrary/venv/lib/python3.7/site-packages/requests/api.py", line 60, in request
    return session.request(method=method, url=url, **kwargs)
  File "/Users/gring2/workspace/bookMarkLibrary/venv/lib/python3.7/site-packages/requests/sessions.py", line 533, in request
    resp = self.send(prep, **send_kwargs)
  File "/Users/gring2/workspace/bookMarkLibrary/venv/lib/python3.7/site-packages/requests/sessions.py", line 646, in send
    r = adapter.send(request, **kwargs)
  File "/Users/gring2/workspace/bookMarkLibrary/venv/lib/python3.7/site-packages/requests/adapters.py", line 516, in send
    raise ConnectionError(e, request=request)
requests.exceptions.ConnectionError: HTTPConnectionPool(host='sub%20bookmark', port=80): Max retries exceeded with url: / (Caused by NewConnectionError('<urllib3.connection.HTTPConnection object at 0x10f8d0b38>: Failed to establish a new connection: [Errno 8] nodename nor servname provided, or not known'))

2019-05-02 00:56:23,599 - root - ERROR -f test_http.py -m error
2019-05-02 00:56:23,600 - root - WARNING -f test_http.py -m critical
2019-05-02 00:56:23,600 - root - CRITICAL -f test_http.py -m warning
2019-05-02 00:56:24,424 - root - ERROR -f models.py -m Traceback (most recent call last):
  File "/Users/gring2/workspace/bookMarkLibrary/venv/lib/python3.7/site-packages/urllib3/connection.py", line 159, in _new_conn
    (self._dns_host, self.port), self.timeout, **extra_kw)
  File "/Users/gring2/workspace/bookMarkLibrary/venv/lib/python3.7/site-packages/urllib3/util/connection.py", line 57, in create_connection
    for res in socket.getaddrinfo(host, port, family, socket.SOCK_STREAM):
  File "/usr/local/Cellar/python/3.7.3/Frameworks/Python.framework/Versions/3.7/lib/python3.7/socket.py", line 748, in getaddrinfo
    for res in _socket.getaddrinfo(host, port, family, type, proto, flags):
socket.gaierror: [Errno 8] nodename nor servname provided, or not known

During handling of the above exception, another exception occurred:

Traceback (most recent call last):
  File "/Users/gring2/workspace/bookMarkLibrary/venv/lib/python3.7/site-packages/urllib3/connectionpool.py", line 600, in urlopen
    chunked=chunked)
  File "/Users/gring2/workspace/bookMarkLibrary/venv/lib/python3.7/site-packages/urllib3/connectionpool.py", line 354, in _make_request
    conn.request(method, url, **httplib_request_kw)
  File "/usr/local/Cellar/python/3.7.3/Frameworks/Python.framework/Versions/3.7/lib/python3.7/http/client.py", line 1229, in request
    self._send_request(method, url, body, headers, encode_chunked)
  File "/usr/local/Cellar/python/3.7.3/Frameworks/Python.framework/Versions/3.7/lib/python3.7/http/client.py", line 1275, in _send_request
    self.endheaders(body, encode_chunked=encode_chunked)
  File "/usr/local/Cellar/python/3.7.3/Frameworks/Python.framework/Versions/3.7/lib/python3.7/http/client.py", line 1224, in endheaders
    self._send_output(message_body, encode_chunked=encode_chunked)
  File "/usr/local/Cellar/python/3.7.3/Frameworks/Python.framework/Versions/3.7/lib/python3.7/http/client.py", line 1016, in _send_output
    self.send(msg)
  File "/usr/local/Cellar/python/3.7.3/Frameworks/Python.framework/Versions/3.7/lib/python3.7/http/client.py", line 956, in send
    self.connect()
  File "/Users/gring2/workspace/bookMarkLibrary/venv/lib/python3.7/site-packages/urllib3/connection.py", line 181, in connect
    conn = self._new_conn()
  File "/Users/gring2/workspace/bookMarkLibrary/venv/lib/python3.7/site-packages/urllib3/connection.py", line 168, in _new_conn
    self, "Failed to establish a new connection: %s" % e)
urllib3.exceptions.NewConnectionError: <urllib3.connection.HTTPConnection object at 0x10dde02b0>: Failed to establish a new connection: [Errno 8] nodename nor servname provided, or not known

During handling of the above exception, another exception occurred:

Traceback (most recent call last):
  File "/Users/gring2/workspace/bookMarkLibrary/venv/lib/python3.7/site-packages/requests/adapters.py", line 449, in send
    timeout=timeout
  File "/Users/gring2/workspace/bookMarkLibrary/venv/lib/python3.7/site-packages/urllib3/connectionpool.py", line 638, in urlopen
    _stacktrace=sys.exc_info()[2])
  File "/Users/gring2/workspace/bookMarkLibrary/venv/lib/python3.7/site-packages/urllib3/util/retry.py", line 398, in increment
    raise MaxRetryError(_pool, url, error or ResponseError(cause))
urllib3.exceptions.MaxRetryError: HTTPConnectionPool(host='sub%20bookmark', port=80): Max retries exceeded with url: / (Caused by NewConnectionError('<urllib3.connection.HTTPConnection object at 0x10dde02b0>: Failed to establish a new connection: [Errno 8] nodename nor servname provided, or not known'))

During handling of the above exception, another exception occurred:

Traceback (most recent call last):
  File "/Users/gring2/workspace/bookMarkLibrary/library/models.py", line 90, in save
    file_name = create_thumbnail(self.url)
  File "/Users/gring2/workspace/bookMarkLibrary/handlers/thumbnail_handler.py", line 8, in create_thumbnail
    response = requests.get(url)
  File "/Users/gring2/workspace/bookMarkLibrary/venv/lib/python3.7/site-packages/requests/api.py", line 75, in get
    return request('get', url, params=params, **kwargs)
  File "/Users/gring2/workspace/bookMarkLibrary/venv/lib/python3.7/site-packages/requests/api.py", line 60, in request
    return session.request(method=method, url=url, **kwargs)
  File "/Users/gring2/workspace/bookMarkLibrary/venv/lib/python3.7/site-packages/requests/sessions.py", line 533, in request
    resp = self.send(prep, **send_kwargs)
  File "/Users/gring2/workspace/bookMarkLibrary/venv/lib/python3.7/site-packages/requests/sessions.py", line 646, in send
    r = adapter.send(request, **kwargs)
  File "/Users/gring2/workspace/bookMarkLibrary/venv/lib/python3.7/site-packages/requests/adapters.py", line 516, in send
    raise ConnectionError(e, request=request)
requests.exceptions.ConnectionError: HTTPConnectionPool(host='sub%20bookmark', port=80): Max retries exceeded with url: / (Caused by NewConnectionError('<urllib3.connection.HTTPConnection object at 0x10dde02b0>: Failed to establish a new connection: [Errno 8] nodename nor servname provided, or not known'))

